<?xml version="1.0"?>
<robot name="diffbot" xmlns:xacro="http://ros.org/wiki/xacro">

  <xacro:property name="wheel_radius" value="0.05"/>
  <xacro:property name="wheel_width" value="0.02"/>
  <xacro:property name="base_length" value="0.4"/>
  <xacro:property name="base_width"  value="0.3"/>

  <!-- Base -->
  <link name="base_link">
    <visual>
      <geometry>
        <box size="${base_length} ${base_width} 0.1"/>
      </geometry>
      <origin xyz="0 0 0.05"/>
    </visual>
    <collision>
      <geometry>
        <box size="${base_length} ${base_width} 0.1"/>
      </geometry>
      <origin xyz="0 0 0.05"/>
    </collision>
    <inertial>
      <mass value="10"/>
      <inertia 
        ixx="0.1" ixy="0.0" ixz="0.0"
        iyy="0.1" iyz="0.0" izz="0.1"/>
      </inertial>
  </link>

  <!-- Wheels -->
  <xacro:macro name="wheel" params="side x_pos">
    <link name="${side}_wheel">
      <visual>
        <geometry>
          <cylinder radius="${wheel_radius}" length="${wheel_width}"/>
        </geometry>
        <origin rpy="0 1.5708 0"/>
      </visual>
      <collision>
        <geometry>
          <cylinder radius="${wheel_radius}" length="${wheel_width}"/>
        </geometry>
        <origin rpy="0 1.5708 0"/>
      </collision>
      <inertial>
        <mass value="1"/>
        <inertia 
          ixx="0.01" ixy="0.0" ixz="0.0"
          iyy="0.01" iyz="0.0" izz="0.01"/>
        </inertial>
    </link>
    <joint name="${side}_wheel_joint" type="continuous">
      <parent link="base_link"/>
      <child link="${side}_wheel"/>
      <origin xyz="${x_pos} ${'0.15' if side == 'left' else '-0.15'} 0.05"/>
      <axis xyz="0 0 1"/>
    </joint>
  </xacro:macro>

  <xacro:wheel side="left" x_pos="0"/>
  <xacro:wheel side="right" x_pos="0"/>

  <!-- Camera -->
  <link name="camera_link">
    <visual>
      <geometry><box size="0.05 0.05 0.05"/></geometry>
    </visual>
  </link>
  <joint name="camera_joint" type="fixed">
    <parent link="base_link"/>
    <child link="camera_link"/>
    <origin xyz="0.1 0 0.2" rpy="0 0 0"/>
  </joint>

  <!-- Lidar -->
  <link name="lidar_link">
    <visual>
      <geometry><cylinder radius="0.03" length="0.05"/></geometry>
      <origin rpy="0 0 0"/>
    </visual>
  </link>
  <joint name="lidar_joint" type="fixed">
    <parent link="base_link"/>
    <child link="lidar_link"/>
    <origin xyz="0 0 0.15"/>
  </joint>

  <!-- Plugins -->
  <gazebo>
    <plugin name="diff_drive_controller" filename="libgazebo_ros_diff_drive.so">
      <left_wheel>left_wheel</left_wheel>
      <right_wheel>right_wheel</right_wheel>
      <wheel_separation>0.3</wheel_separation>
      <wheel_diameter>0.1</wheel_diameter>
      <robot_base_frame>base_link</robot_base_frame>
      <updateRate>50</updateRate>
      <commandTopic>cmd_vel</commandTopic>
      <odometryTopic>odom</odometryTopic>
    </plugin>

    <plugin name="camera_controller" filename="libgazebo_ros_camera.so">
      <alwaysOn>true</alwaysOn>
      <cameraName>robot_camera</cameraName>
      <imageTopicName>camera/image_raw</imageTopicName>
      <cameraInfoTopicName>camera/camera_info</cameraInfoTopicName>
      <frameName>camera_link</frameName>
    </plugin>

    <plugin name="lidar_controller" filename="libgazebo_ros_laser.so">
      <topicName>scan</topicName>
      <frameName>lidar_link</frameName>
    </plugin>
  </gazebo>

</robot>
