<?xml version="1.0"?>
<robot name="diffbot">

  <!-- Base -->
  <link name="base_link">
    <visual>
      <geometry>
        <box size="0.4 0.3 0.1"/>
      </geometry>
      <origin xyz="0 0 0.05"/>
    </visual>
    <collision>
      <geometry>
        <box size="0.4 0.3 0.1"/>
      </geometry>
      <origin xyz="0 0 0.05"/>
    </collision>
    <inertial>
      <mass value="10"/>
      <inertia ixx="0.1" iyy="0.1" izz="0.1"/>
    </inertial>
  </link>

  <!-- Left Wheel -->
  <link name="left_wheel">
    <visual>
      <geometry>
        <cylinder radius="0.05" length="0.02"/>
      </geometry>
      <origin rpy="0 1.5708 0"/>
    </visual>
    <collision>
      <geometry>
        <cylinder radius="0.05" length="0.02"/>
      </geometry>
      <origin rpy="0 1.5708 0"/>
    </collision>
    <inertial>
      <mass value="1"/>
      <inertia ixx="0.01" iyy="0.01" izz="0.01"/>
    </inertial>
  </link>
  <joint name="left_wheel_joint" type="continuous">
    <parent link="base_link"/>
    <child link="left_wheel"/>
    <origin xyz="0 0.15 0.05"/>
    <axis xyz="0 0 1"/>
  </joint>

  <!-- Right Wheel -->
  <link name="right_wheel">
    <visual>
      <geometry>
        <cylinder radius="0.05" length="0.02"/>
      </geometry>
      <origin rpy="0 1.5708 0"/>
    </visual>
    <collision>
      <geometry>
        <cylinder radius="0.05" length="0.02"/>
      </geometry>
      <origin rpy="0 1.5708 0"/>
    </collision>
    <inertial>
      <mass value="1"/>
      <inertia ixx="0.01" iyy="0.01" izz="0.01"/>
    </inertial>
  </link>
  <joint name="right_wheel_joint" type="continuous">
    <parent link="base_link"/>
    <child link="right_wheel"/>
    <origin xyz="0 -0.15 0.05"/>
    <axis xyz="0 0 1"/>
  </joint>

  <!-- Camera -->
  <link name="camera_link">
    <visual>
      <geometry><box size="0.05 0.05 0.05"/></geometry>
    </visual>
  </link>
  <joint name="camera_joint" type="fixed">
    <parent link="base_link"/>
    <child link="camera_link"/>
    <origin xyz="0.1 0 0.2" rpy="0 0 0"/>
  </joint>

  <!-- Lidar -->
  <link name="lidar_link">
    <visual>
      <geometry><cylinder radius="0.03" length="0.05"/></geometry>
      <origin rpy="0 0 0"/>
    </visual>
  </link>
  <joint name="lidar_joint" type="fixed">
    <parent link="base_link"/>
    <child link="lidar_link"/>
    <origin xyz="0 0 0.15"/>
  </joint>

</robot>
